2025-05-11 16:36:36,673:INFO:Processed 0, Total Processed: 1 Papers
2025-05-11 16:36:36,682:INFO:Data successfully appended to file: ../Pruebas/SalidaRSEF1/fgcs2017/processed_metadata.json
2025-05-11 16:36:36,695:INFO:Successfully opened JSON
2025-05-11 16:36:36,695:INFO:Analyzing directionality for 10.1007/978-94-009-2991-3_4
2025-05-11 16:36:36,696:INFO:Checking bidirectional links
2025-05-11 16:36:59,132:ERROR:ERROR:https://github.com/dgarijo/OPMWValidator SOMEF failed due to: SOMEF Command failed with return code 1: 11-May-25 16:36:59-DEBUG-Starting new HTTPS connection (1): github.com:443
11-May-25 16:36:59-DEBUG-https://github.com:443 "GET /api/v4/projects HTTP/1.1" 404 9
11-May-25 16:36:59-INFO-Loading Repository https://github.com/dgarijo/OPMWValidator Information....
11-May-25 16:36:59-DEBUG-Starting new HTTPS connection (1): api.github.com:443
11-May-25 16:36:57-DEBUG-https://api.github.com:443 "GET /repos/dgarijo/OPMWValidator HTTP/1.1" 200 None
11-May-25 16:36:57-INFO-Remaining GitHub API requests: 4797 ### Next rate limit reset at: 2025-05-11 16:55:09
11-May-25 16:36:57-ERROR-Error: key license not present in github repository
11-May-25 16:36:57-ERROR-Error: key description not present in github repository
11-May-25 16:36:57-DEBUG-Starting new HTTPS connection (1): api.github.com:443
11-May-25 16:36:57-DEBUG-https://api.github.com:443 "GET /repos/dgarijo/OPMWValidator/languages HTTP/1.1" 200 14
11-May-25 16:36:57-INFO-Remaining GitHub API requests: 4796 ### Next rate limit reset at: 2025-05-11 16:55:09
11-May-25 16:36:57-DEBUG-Starting new HTTPS connection (1): api.github.com:443
11-May-25 16:36:58-DEBUG-https://api.github.com:443 "GET /repos/dgarijo/OPMWValidator/releases HTTP/1.1" 200 2
11-May-25 16:36:58-INFO-Remaining GitHub API requests: 4795 ### Next rate limit reset at: 2025-05-11 16:55:09
11-May-25 16:36:58-INFO-Repository information successfully loaded.

11-May-25 16:36:58-INFO-Downloading https://github.com/dgarijo/OPMWValidator/archive/master.zip
11-May-25 16:36:58-DEBUG-Starting new HTTPS connection (1): github.com:443
11-May-25 16:36:58-DEBUG-https://github.com:443 "GET /dgarijo/OPMWValidator/archive/master.zip HTTP/1.1" 302 0
11-May-25 16:36:58-DEBUG-Starting new HTTPS connection (1): codeload.github.com:443
Traceback (most recent call last):
  File "/home/raaquel/entornosVirtuales/nuevoRSEF/lib/python3.12/site-packages/urllib3/connectionpool.py", line 464, in _make_request
    self._validate_conn(conn)
  File "/home/raaquel/entornosVirtuales/nuevoRSEF/lib/python3.12/site-packages/urllib3/connectionpool.py", line 1093, in _validate_conn
    conn.connect()
  File "/home/raaquel/entornosVirtuales/nuevoRSEF/lib/python3.12/site-packages/urllib3/connection.py", line 741, in connect
    sock_and_verified = _ssl_wrap_socket_and_match_hostname(
                        ^^^^^^^^^^^^^^^^^^^^^^^^^^^^^^^^^^^^
  File "/home/raaquel/entornosVirtuales/nuevoRSEF/lib/python3.12/site-packages/urllib3/connection.py", line 920, in _ssl_wrap_socket_and_match_hostname
    ssl_sock = ssl_wrap_socket(
               ^^^^^^^^^^^^^^^^
  File "/home/raaquel/entornosVirtuales/nuevoRSEF/lib/python3.12/site-packages/urllib3/util/ssl_.py", line 480, in ssl_wrap_socket
    ssl_sock = _ssl_wrap_socket_impl(sock, context, tls_in_tls, server_hostname)
               ^^^^^^^^^^^^^^^^^^^^^^^^^^^^^^^^^^^^^^^^^^^^^^^^^^^^^^^^^^^^^^^^^
  File "/home/raaquel/entornosVirtuales/nuevoRSEF/lib/python3.12/site-packages/urllib3/util/ssl_.py", line 524, in _ssl_wrap_socket_impl
    return ssl_context.wrap_socket(sock, server_hostname=server_hostname)
           ^^^^^^^^^^^^^^^^^^^^^^^^^^^^^^^^^^^^^^^^^^^^^^^^^^^^^^^^^^^^^^
  File "/usr/lib/python3.12/ssl.py", line 455, in wrap_socket
    return self.sslsocket_class._create(
           ^^^^^^^^^^^^^^^^^^^^^^^^^^^^^
  File "/usr/lib/python3.12/ssl.py", line 1042, in _create
    self.do_handshake()
  File "/usr/lib/python3.12/ssl.py", line 1320, in do_handshake
    self._sslobj.do_handshake()
ssl.SSLError: [SSL: DECRYPTION_FAILED_OR_BAD_RECORD_MAC] decryption failed or bad record mac (_ssl.c:1000)

During handling of the above exception, another exception occurred:

Traceback (most recent call last):
  File "/home/raaquel/entornosVirtuales/nuevoRSEF/lib/python3.12/site-packages/urllib3/connectionpool.py", line 787, in urlopen
    response = self._make_request(
               ^^^^^^^^^^^^^^^^^^^
  File "/home/raaquel/entornosVirtuales/nuevoRSEF/lib/python3.12/site-packages/urllib3/connectionpool.py", line 488, in _make_request
    raise new_e
urllib3.exceptions.SSLError: [SSL: DECRYPTION_FAILED_OR_BAD_RECORD_MAC] decryption failed or bad record mac (_ssl.c:1000)

The above exception was the direct cause of the following exception:

Traceback (most recent call last):
  File "/home/raaquel/entornosVirtuales/nuevoRSEF/lib/python3.12/site-packages/requests/adapters.py", line 667, in send
    resp = conn.urlopen(
           ^^^^^^^^^^^^^
  File "/home/raaquel/entornosVirtuales/nuevoRSEF/lib/python3.12/site-packages/urllib3/connectionpool.py", line 841, in urlopen
    retries = retries.increment(
              ^^^^^^^^^^^^^^^^^^
  File "/home/raaquel/entornosVirtuales/nuevoRSEF/lib/python3.12/site-packages/urllib3/util/retry.py", line 519, in increment
    raise MaxRetryError(_pool, url, reason) from reason  # type: ignore[arg-type]
    ^^^^^^^^^^^^^^^^^^^^^^^^^^^^^^^^^^^^^^^^^^^^^^^^^^^
urllib3.exceptions.MaxRetryError: HTTPSConnectionPool(host='codeload.github.com', port=443): Max retries exceeded with url: /dgarijo/OPMWValidator/zip/refs/heads/master (Caused by SSLError(SSLError(1, '[SSL: DECRYPTION_FAILED_OR_BAD_RECORD_MAC] decryption failed or bad record mac (_ssl.c:1000)')))

During handling of the above exception, another exception occurred:

Traceback (most recent call last):
  File "/home/raaquel/entornosVirtuales/nuevoRSEF/bin/somef", line 8, in <module>
    sys.exit(cli())
             ^^^^^
  File "/home/raaquel/entornosVirtuales/nuevoRSEF/lib/python3.12/site-packages/click/core.py", line 1161, in __call__
    return self.main(*args, **kwargs)
           ^^^^^^^^^^^^^^^^^^^^^^^^^^
  File "/home/raaquel/entornosVirtuales/nuevoRSEF/lib/python3.12/site-packages/click/core.py", line 1082, in main
    rv = self.invoke(ctx)
         ^^^^^^^^^^^^^^^^
  File "/home/raaquel/entornosVirtuales/nuevoRSEF/lib/python3.12/site-packages/click/core.py", line 1697, in invoke
    return _process_result(sub_ctx.command.invoke(sub_ctx))
                           ^^^^^^^^^^^^^^^^^^^^^^^^^^^^^^^
  File "/home/raaquel/entornosVirtuales/nuevoRSEF/lib/python3.12/site-packages/click/core.py", line 1443, in invoke
    return ctx.invoke(self.callback, **ctx.params)
           ^^^^^^^^^^^^^^^^^^^^^^^^^^^^^^^^^^^^^^^
  File "/home/raaquel/entornosVirtuales/nuevoRSEF/lib/python3.12/site-packages/click/core.py", line 788, in invoke
    return __callback(*args, **kwargs)
           ^^^^^^^^^^^^^^^^^^^^^^^^^^^
  File "/home/raaquel/entornosVirtuales/nuevoRSEF/lib/python3.12/site-packages/somef/__main__.py", line 163, in describe
    somef_cli.run_cli(**kwargs)
  File "/home/raaquel/entornosVirtuales/nuevoRSEF/lib/python3.12/site-packages/somef/somef_cli.py", line 260, in run_cli
    repo_data = cli_get_data(threshold=threshold, ignore_classifiers=ignore_classifiers, repo_url=repo_url,
                ^^^^^^^^^^^^^^^^^^^^^^^^^^^^^^^^^^^^^^^^^^^^^^^^^^^^^^^^^^^^^^^^^^^^^^^^^^^^^^^^^^^^^^^^^^^
  File "/home/raaquel/entornosVirtuales/nuevoRSEF/lib/python3.12/site-packages/somef/somef_cli.py", line 101, in cli_get_data
    local_folder = process_repository.download_repository_files(owner, repo_name, def_branch, repo_type,
                   ^^^^^^^^^^^^^^^^^^^^^^^^^^^^^^^^^^^^^^^^^^^^^^^^^^^^^^^^^^^^^^^^^^^^^^^^^^^^^^^^^^^^^
  File "/home/raaquel/entornosVirtuales/nuevoRSEF/lib/python3.12/site-packages/somef/process_repository.py", line 595, in download_repository_files
    return download_github_files(target_dir, owner, repo_name, default_branch, authorization)
           ^^^^^^^^^^^^^^^^^^^^^^^^^^^^^^^^^^^^^^^^^^^^^^^^^^^^^^^^^^^^^^^^^^^^^^^^^^^^^^^^^^
  File "/home/raaquel/entornosVirtuales/nuevoRSEF/lib/python3.12/site-packages/somef/process_repository.py", line 621, in download_github_files
    repo_download, date = rate_limit_get(repo_archive_url, headers=header_template(authorization))
                          ^^^^^^^^^^^^^^^^^^^^^^^^^^^^^^^^^^^^^^^^^^^^^^^^^^^^^^^^^^^^^^^^^^^^^^^^
  File "/home/raaquel/entornosVirtuales/nuevoRSEF/lib/python3.12/site-packages/somef/process_repository.py", line 47, in rate_limit_get
    response = requests.get(*args, **kwargs)
               ^^^^^^^^^^^^^^^^^^^^^^^^^^^^^
  File "/home/raaquel/entornosVirtuales/nuevoRSEF/lib/python3.12/site-packages/requests/api.py", line 73, in get
    return request("get", url, params=params, **kwargs)
           ^^^^^^^^^^^^^^^^^^^^^^^^^^^^^^^^^^^^^^^^^^^^
  File "/home/raaquel/entornosVirtuales/nuevoRSEF/lib/python3.12/site-packages/requests/api.py", line 59, in request
    return session.request(method=method, url=url, **kwargs)
           ^^^^^^^^^^^^^^^^^^^^^^^^^^^^^^^^^^^^^^^^^^^^^^^^^
  File "/home/raaquel/entornosVirtuales/nuevoRSEF/lib/python3.12/site-packages/requests/sessions.py", line 589, in request
    resp = self.send(prep, **send_kwargs)
           ^^^^^^^^^^^^^^^^^^^^^^^^^^^^^^
  File "/home/raaquel/entornosVirtuales/nuevoRSEF/lib/python3.12/site-packages/requests/sessions.py", line 724, in send
    history = [resp for resp in gen]
              ^^^^^^^^^^^^^^^^^^^^^^
  File "/home/raaquel/entornosVirtuales/nuevoRSEF/lib/python3.12/site-packages/requests/sessions.py", line 265, in resolve_redirects
    resp = self.send(
           ^^^^^^^^^^
  File "/home/raaquel/entornosVirtuales/nuevoRSEF/lib/python3.12/site-packages/requests/sessions.py", line 703, in send
    r = adapter.send(request, **kwargs)
        ^^^^^^^^^^^^^^^^^^^^^^^^^^^^^^^
  File "/home/raaquel/entornosVirtuales/nuevoRSEF/lib/python3.12/site-packages/requests/adapters.py", line 698, in send
    raise SSLError(e, request=request)
requests.exceptions.SSLError: HTTPSConnectionPool(host='codeload.github.com', port=443): Max retries exceeded with url: /dgarijo/OPMWValidator/zip/refs/heads/master (Caused by SSLError(SSLError(1, '[SSL: DECRYPTION_FAILED_OR_BAD_RECORD_MAC] decryption failed or bad record mac (_ssl.c:1000)')))

2025-05-11 16:36:59,135:INFO:Issue while downloading the repository for 10.1007/978-94-009-2991-3_4
2025-05-11 16:36:59,136:INFO:Checking unidirectional links
2025-05-11 16:37:18,193:INFO:Data successfully appended to file: ../Pruebas/SalidaRSEF1/fgcs2017/url_search_output.json
2025-05-11 16:37:18,212:INFO:Output saved to: ../Pruebas/SalidaRSEF1/fgcs2017/url_search_output.json
